Traceback (most recent call last):
  File "/home/robson/miniconda3/envs/book/lib/python3.9/site-packages/jupyter_cache/executors/utils.py", line 58, in single_nb_execution
    executenb(
  File "/home/robson/miniconda3/envs/book/lib/python3.9/site-packages/nbclient/client.py", line 1204, in execute
    return NotebookClient(nb=nb, resources=resources, km=km, **kwargs).execute()
  File "/home/robson/miniconda3/envs/book/lib/python3.9/site-packages/nbclient/util.py", line 84, in wrapped
    return just_run(coro(*args, **kwargs))
  File "/home/robson/miniconda3/envs/book/lib/python3.9/site-packages/nbclient/util.py", line 62, in just_run
    return loop.run_until_complete(coro)
  File "/home/robson/miniconda3/envs/book/lib/python3.9/asyncio/base_events.py", line 647, in run_until_complete
    return future.result()
  File "/home/robson/miniconda3/envs/book/lib/python3.9/site-packages/nbclient/client.py", line 663, in async_execute
    await self.async_execute_cell(
  File "/home/robson/miniconda3/envs/book/lib/python3.9/site-packages/nbclient/client.py", line 965, in async_execute_cell
    await self._check_raise_for_error(cell, cell_index, exec_reply)
  File "/home/robson/miniconda3/envs/book/lib/python3.9/site-packages/nbclient/client.py", line 862, in _check_raise_for_error
    raise CellExecutionError.from_cell_and_msg(cell, exec_reply_content)
nbclient.exceptions.CellExecutionError: An error occurred while executing the following cell:
------------------
nome = input('Qual seu nome? ')
idade = int(input('Qual sua idade? '))
altura = float(input('Qual sua altura? '))
peso = float(input('Qual seu peso? '))

print('Nome: %s' % nome)
print('Idade: %d' % idade)

imc = peso / ( altura * altura )
print('O IMC =', imc)
print('Muito abaixo do peso:', imc < 17)
print('Abaixo do peso normal:', imc >= 17 and imc < 18.5)
print('Peso dentro do normal:', imc >= 18.5 and imc < 25.0)
print('Acima do peso normal:', imc >= 25 and imc < 30)
print('Muito acima do peso:', imc >= 30)
------------------

[0;31m---------------------------------------------------------------------------[0m
[0;31mStdinNotImplementedError[0m                  Traceback (most recent call last)
Cell [0;32mIn[11], line 1[0m
[0;32m----> 1[0m nome [38;5;241m=[39m [38;5;28;43minput[39;49m[43m([49m[38;5;124;43m'[39;49m[38;5;124;43mQual seu nome? [39;49m[38;5;124;43m'[39;49m[43m)[49m
[1;32m      2[0m idade [38;5;241m=[39m [38;5;28mint[39m([38;5;28minput[39m([38;5;124m'[39m[38;5;124mQual sua idade? [39m[38;5;124m'[39m))
[1;32m      3[0m altura [38;5;241m=[39m [38;5;28mfloat[39m([38;5;28minput[39m([38;5;124m'[39m[38;5;124mQual sua altura? [39m[38;5;124m'[39m))

File [0;32m~/miniconda3/envs/book/lib/python3.9/site-packages/ipykernel/kernelbase.py:1190[0m, in [0;36mKernel.raw_input[0;34m(self, prompt)[0m
[1;32m   1188[0m [38;5;28;01mif[39;00m [38;5;129;01mnot[39;00m [38;5;28mself[39m[38;5;241m.[39m_allow_stdin:
[1;32m   1189[0m     msg [38;5;241m=[39m [38;5;124m"[39m[38;5;124mraw_input was called, but this frontend does not support input requests.[39m[38;5;124m"[39m
[0;32m-> 1190[0m     [38;5;28;01mraise[39;00m StdinNotImplementedError(msg)
[1;32m   1191[0m [38;5;28;01mreturn[39;00m [38;5;28mself[39m[38;5;241m.[39m_input_request(
[1;32m   1192[0m     [38;5;28mstr[39m(prompt),
[1;32m   1193[0m     [38;5;28mself[39m[38;5;241m.[39m_parent_ident[[38;5;124m"[39m[38;5;124mshell[39m[38;5;124m"[39m],
[1;32m   1194[0m     [38;5;28mself[39m[38;5;241m.[39mget_parent([38;5;124m"[39m[38;5;124mshell[39m[38;5;124m"[39m),
[1;32m   1195[0m     password[38;5;241m=[39m[38;5;28;01mFalse[39;00m,
[1;32m   1196[0m )

[0;31mStdinNotImplementedError[0m: raw_input was called, but this frontend does not support input requests.
StdinNotImplementedError: raw_input was called, but this frontend does not support input requests.

